<?xml version="1.0"?>
<robot xmlns:xacro="http://www.ros.org/wiki/xacro" >
<xacro:include filename="inertial_macros.xacro" />

    <joint name="arm_joint" type="revolute">
        <parent link="chassis"/>
        <child link="arm"/>
        <origin xyz="0.25 0 0.32" rpy="0 0 0"/>
    	<axis xyz="0 1 0"/>
    	<limit effort="50" velocity="1" lower="-0.35" upper="2.3"/>
    	<dynamics damping="1" friction="1"/>
    </joint>
    
    
    <link name="arm">
        <visual>
            <origin xyz="0 0 0.1725" rpy="0 0 0"/>
            <geometry>
                <box size="0.03 0.03 0.4"/>
            </geometry>
        </visual>
        <collision>
            <origin xyz="0 0 0.1725" rpy="0 0 0"/>
            <geometry>
                <box size="0.03 0.03 0.4"/>
            </geometry>
        </collision>
        <xacro:inertial_box mass="0.08" x="0.03" y="0.03" z="0.4">
            <origin xyz="0 0 0" rpy="0 0 0"/>
        </xacro:inertial_box>
    </link>
    <gazebo reference="arm">
  	<material>Gazebo/Blue</material>
    </gazebo>
    
    <joint name="palm_joint" type="fixed">
        <parent link="arm"/>
        <child link="palm"/>
        <origin xyz="0 0 0.37" rpy="-0.7 0 1.5708"/>
    </joint>
 
    <link name="palm">
        <visual>
            <origin xyz="0 0 0" rpy="0 0 0"/>
            <geometry>
                <box size="0.14 0.025 0.02"/>
            </geometry>
        </visual>
        <collision>
            <origin xyz="0 0 0" rpy="0 0 0"/>
            <geometry>
                <box size="0.14 0.025 0.02"/>
            </geometry>
        </collision>
        <xacro:inertial_box mass="0.07" x="0.1" y="0.025" z="0.02">
            <origin xyz="0 0 0" rpy="0 0 0"/>
        </xacro:inertial_box>
    </link>
    <gazebo reference="palm">
  	<material>Gazebo/Blue</material>
    </gazebo>
    
    
    <joint name="finger1_joint" type="prismatic">
        <parent link="palm"/>
        <child link="finger1"/>
        <origin xyz="0.07 0 0" rpy="0 0 0"/>
        <axis xyz="-1 0 0"/> 
        <limit effort="50" velocity="1" lower="0" upper="0.06"/>
        <dynamics damping="1" friction="2"/>
    </joint>
    
    
    <link name="finger1">
        <visual>
            <origin xyz="0.01 0 0.05" rpy="0 0 0"/>
            <geometry>
                <box size="0.03 0.02 0.1"/>
            </geometry>
        </visual>
        <collision>
            <origin xyz="0.01 0 0.05" rpy="0 0 0"/>
            <geometry>
                <box size="0.03 0.02 0.1"/>
            </geometry>
        </collision>
        <xacro:inertial_box mass="0.05" x="0.03" y="0.02" z="0.1">
            <origin xyz="0 0 0" rpy="0 0 0"/>
        </xacro:inertial_box>
    </link>
    <gazebo reference="finger1">
  	<material>Gazebo/Red</material>
  	<selfCollide>false</selfCollide>
    </gazebo>
    
    
    
    <joint name="finger2_joint" type="prismatic">
        <parent link="palm"/>
        <child link="finger2"/>
        <origin xyz="-0.07 0 0" rpy="0 0 0"/>
        <axis xyz="1 0 0"/> 
        <limit effort="50" velocity="1" lower="0" upper="0.06"/>
        <dynamics damping="1" friction="2" />
    </joint>
    
    


    <link name="finger2">
        <visual>
            <origin xyz="-0.01 0 0.05" rpy="0 0 0"/>
            <geometry>
                <box size="0.03 0.02 0.1"/>
            </geometry>
        </visual>
        <collision>
            <origin xyz="-0.01 0 0.05" rpy="0 0 0"/>
            <geometry>
                <box size="0.03 0.02 0.1"/>
            </geometry>
        </collision>
        <xacro:inertial_box mass="0.05" x="0.03" y="0.02" z="0.1">
            <origin xyz="0 0 0" rpy="0 0 0"/>
        </xacro:inertial_box>
    </link>
    <gazebo reference="finger2">
  	<material>Gazebo/Red</material>
  	<selfCollide>false</selfCollide>
    </gazebo>
 
    
 
    
    
    
</robot>
