<?xml version="1.0"?>
<robot xmlns:xacro="http://www.ros.org/wiki/xacro" >
<xacro:include filename="inertial_macros.xacro" />
    <material name="white">
        <color rgba="1 1 1 1" />
    </material>

    <material name="orange">
        <color rgba="1 0.3 0.1 1"/>
    </material>

    <material name="blue">
        <color rgba="0.2 0.2 1 1"/>
    </material>

    <material name="black">
        <color rgba="0 0 0 1"/>
    </material>

    <material name="red">
        <color rgba="1 0 0 1"/>
    </material>

    <!-- BASE LINK -->

    <link name="base_link">

    </link>
    
    <!-- BASE_FOOTPRINT LINK -->

    <joint name="base_footprint_joint" type="fixed">
    <parent link="base_link"/>
    <child link="base_footprint"/>
    <origin xyz="0 0 0" rpy="0 0 0"/>
    </joint>

    <link name="base_footprint">
    </link>
    
    <joint name="chassis_joint" type="fixed">
    <parent link="base_link"/>
    <child link="chassis"/>
    <origin xyz="0 0 0"/>
    </joint>
    
    <link name="chassis">
    <visual>
        <origin xyz="0.0 0 0.25" rpy="0 0 0"/>
        <geometry>
            <box size="0.5 0.3 0.02"/>
            <!--mesh filename="file:///home/tien/colcon_ws/articubot_one/description/body.dae" scale="1 1 1"/-->
        </geometry>
        <material name="white"/>
    </visual>
    <collision>
        <origin xyz="0.0 0 0.25" rpy="0 0 0"/>
        <geometry>
            <box size="0.5 0.3 0.02"/>
            <!--mesh filename="file:///home/tien/colcon_ws/articubot_one/description/body.dae" scale="1 1 1"/-->
        </geometry>
    </collision>
    <xacro:inertial_box mass="25" x="0.5" y="0.3" z="0.02">
        <origin xyz="0 0 0.25" rpy="0 0 0"/>
    </xacro:inertial_box>
    </link>
    <gazebo reference="chassis">
    <material>Gazebo/White</material>
    </gazebo>
    
    <joint name="chassis_joint1" type="fixed">
    <parent link="base_link"/>
    <child link="chassissidel"/>
    <origin xyz="0 0 0"/>
    </joint>
    
    <link name="chassissidel">
    <visual>
        <origin xyz="0 0.15 0.32" rpy="0 0 0"/>
        <geometry>
            <box size="0.5 0.02 0.1"/>
        </geometry>
        <material name="white"/>
    </visual>
    <collision>
        <origin xyz="0 0.15 0.32" rpy="0 0 0"/>
        <geometry>
            <box size="0.5 0.02 0.1"/>
        </geometry>
    </collision>
    <xacro:inertial_box mass="0.75" x="0.5" y="0.02" z="0.1">
        <origin xyz="0 0.15 0.32" rpy="0 0 0"/>
    </xacro:inertial_box>
    </link>
    <gazebo reference="chassissidel">
    <material>Gazebo/White</material>
    </gazebo>
    
    <joint name="chassis_joint2" type="fixed">
    <parent link="base_link"/>
    <child link="chassissider"/>
    <origin xyz="0 0 0"/>
    </joint>
    
    <link name="chassissider">
    <visual>
        <origin xyz="0 -0.15 0.32" rpy="0 0 0"/>
        <geometry>
            <box size="0.5 0.02 0.1"/>
        </geometry>
        <material name="white"/>
    </visual>
    <collision>
        <origin xyz="0 -0.15 0.32" rpy="0 0 0"/>
        <geometry>
            <box size="0.5 0.02 0.1"/>
        </geometry>
    </collision>
    <xacro:inertial_box mass="0.75" x="0.5" y="0.02" z="0.1">
        <origin xyz="0 -0.15 0.32" rpy="0 0 0"/>
    </xacro:inertial_box>
    </link>
    <gazebo reference="chassissider">
    <material>Gazebo/White</material>
    </gazebo>
    
    <joint name="chassis_joint3" type="fixed">
    <parent link="base_link"/>
    <child link="chassissidef"/>
    <origin xyz="0 0 0"/>
    </joint>
    
    <link name="chassissidef">
    <visual>
        <origin xyz="0.2 0 0.32" rpy="0 0 0"/>
        <geometry>
            <box size="0.02 0.3 0.1"/>
        </geometry>
        <material name="white"/>
    </visual>
    <collision>
        <origin xyz="0.2 0 0.32" rpy="0 0 0"/>
        <geometry>
            <box size="0.02 0.3 0.1"/>
        </geometry>
    </collision>
    </link>
    <gazebo reference="chassissidef">
    <material>Gazebo/White</material>
    </gazebo>
  
    <joint name="chassis_joint4" type="fixed">
    <parent link="base_link"/>
    <child link="chassissideb"/>
    <origin xyz="0 0 0"/>
    </joint>
    
    <link name="chassissideb">
    <visual>
        <origin xyz="-0.25 0 0.32" rpy="0 0 0"/>
        <geometry>
            <box size="0.02 0.3 0.1"/>
        </geometry>
        <material name="white"/>
    </visual>
    <collision>
        <origin xyz="-0.25 0 0.32" rpy="0 0 0"/>
        <geometry>
            <box size="0.02 0.3 0.1"/>
        </geometry>
    </collision>
    </link>
    <gazebo reference="chassissideb">
    <material>Gazebo/White</material>
    </gazebo>
    
    <joint name="chassis_joint5" type="fixed">
    <parent link="base_link"/>
    <child link="sao_fl"/>
    <origin xyz="0 0 0"/>
    </joint>
    
    <link name="sao_fl">
    <visual>
        <origin xyz="0.25 -0.15 0.2" rpy="0 0 0"/>
        <geometry>
            <box size="0.02 0.02 0.375"/>
        </geometry>
        <material name="white"/>
    </visual>
    <collision>
        <origin xyz="0.25 -0.15 0.2" rpy="0 0 0"/>
        <geometry>
            <box size="0.02 0.02 0.375"/>
        </geometry>
    </collision>
    </link>
    <gazebo reference="sao_fl">
    <material>Gazebo/White</material>
    </gazebo>
    
    <joint name="chassis_joint6" type="fixed">
    <parent link="base_link"/>
    <child link="sao_fr"/>
    <origin xyz="0 0 0"/>
    </joint>
    
    <link name="sao_fr">
    <visual>
        <origin xyz="0.25 0.15 0.2" rpy="0 0 0"/>
        <geometry>
            <box size="0.02 0.02 0.375"/>
        </geometry>
        <material name="white"/>
    </visual>
    <collision>
        <origin xyz="0.25 0.15 0.2" rpy="0 0 0"/>
        <geometry>
            <box size="0.02 0.02 0.375"/>
        </geometry>
    </collision>
    </link>
    <gazebo reference="sao_fr">
    <material>Gazebo/White</material>
    </gazebo>
    
    <joint name="chassis_joint7" type="fixed">
    <parent link="base_link"/>
    <child link="sao_br"/>
    <origin xyz="0 0 0"/>
    </joint>
    
    <link name="sao_br">
    <visual>
        <origin xyz="-0.25 0.15 0.2" rpy="0 0 0"/>
        <geometry>
            <box size="0.02 0.02 0.375"/>
        </geometry>
        <material name="white"/>
    </visual>
    <collision>
        <origin xyz="-0.25 0.15 0.2" rpy="0 0 0"/>
        <geometry>
            <box size="0.02 0.02 0.375"/>
        </geometry>
    </collision>
    </link>
    <gazebo reference="sao_br">
    <material>Gazebo/White</material>
    </gazebo>
    
    <joint name="chassis_joint8" type="fixed">
    <parent link="base_link"/>
    <child link="sao_bl"/>
    <origin xyz="0 0 0"/>
    </joint>
    
    <link name="sao_bl">
    <visual>
        <origin xyz="-0.25 -0.15 0.2" rpy="0 0 0"/>
        <geometry>
            <box size="0.02 0.02 0.375"/>
        </geometry>
        <material name="white"/>
    </visual>
    <collision>
        <origin xyz="-0.25 -0.15 0.2" rpy="0 0 0"/>
        <geometry>
            <box size="0.02 0.02 0.375"/>
        </geometry>
    </collision>
    </link>
    <gazebo reference="sao_bl">
    <material>Gazebo/White</material>
    </gazebo>
    
    <joint name="chassis_joint9" type="fixed">
    <parent link="base_link"/>
    <child link="grippermotor"/>
    <origin xyz="0 0 0"/>
    </joint>
    
    <link name="grippermotor">
    <visual>
        <origin xyz="0.24 0 0.32" rpy="0 0 0"/>
        <geometry>
            <box size="0.07 0.05 0.06"/>
        </geometry>
        <material name="white"/>
    </visual>
    <collision>
        <origin xyz="0.24 0 0.32" rpy="0 0 0"/>
        <geometry>
            <box size="0.07 0.05 0.06"/>
        </geometry>
    </collision>
    </link>
    <gazebo reference="grippermotor">
    <material>Gazebo/White</material>
    </gazebo>
    
    <joint name="chassis_joint10" type="fixed">
    <parent link="base_link"/>
    <child link="drivemotor_fl"/>
    <origin xyz="0 0 0"/>
    </joint>
    
    <link name="drivemotor_fl">
    <visual>
        <origin xyz="0.25 0.15 0.023" rpy="0 0 0"/>
        <geometry>
            <box size="0.04 0.06 0.04"/>
        </geometry>
        <material name="white"/>
    </visual>
    <collision>
        <origin xyz="0.25 0.15 0.023" rpy="0 0 0"/>
        <geometry>
            <box size="0.04 0.06 0.04"/>
        </geometry>
    </collision>
    </link>
    <gazebo reference="drivemotor_fl">
    <material>Gazebo/White</material>
    </gazebo>
    
    <joint name="chassis_joint11" type="fixed">
    <parent link="base_link"/>
    <child link="drivemotor_fr"/>
    <origin xyz="0 0 0"/>
    </joint>
    
    <link name="drivemotor_fr">
    <visual>
        <origin xyz="0.25 -0.15 0.023" rpy="0 0 0"/>
        <geometry>
            <box size="0.04 0.06 0.04"/>
        </geometry>
        <material name="white"/>
    </visual>
    <collision>
        <origin xyz="0.25 -0.15 0.023" rpy="0 0 0"/>
        <geometry>
            <box size="0.04 0.06 0.04"/>
        </geometry>
    </collision>
    </link>
    <gazebo reference="drivemotor_fr">
    <material>Gazebo/White</material>
    </gazebo>
    
    <joint name="chassis_joint12" type="fixed">
    <parent link="base_link"/>
    <child link="drivemotor_br"/>
    <origin xyz="0 0 0"/>
    </joint>
    
    <link name="drivemotor_br">
    <visual>
        <origin xyz="-0.25 -0.15 0.023" rpy="0 0 0"/>
        <geometry>
            <box size="0.03 0.04 0.03"/>
        </geometry>
        <material name="white"/>
    </visual>
    <collision>
        <origin xyz="-0.25 -0.15 0.023" rpy="0 0 0"/>
        <geometry>
            <box size="0.03 0.04 0.03"/>
        </geometry>
    </collision>
    </link>
    <gazebo reference="drivemotor_br">
    <material>Gazebo/White</material>
    </gazebo>
    
    <joint name="chassis_joint13" type="fixed">
    <parent link="base_link"/>
    <child link="drivemotor_bl"/>
    <origin xyz="0 0 0"/>
    </joint>
    
    <link name="drivemotor_bl">
    <visual>
        <origin xyz="-0.25 0.15 0.023" rpy="0 0 0"/>
        <geometry>
            <box size="0.03 0.04 0.03"/>
        </geometry>
        <material name="white"/>
    </visual>
    <collision>
        <origin xyz="-0.25 0.15 0.023" rpy="0 0 0"/>
        <geometry>
            <box size="0.03 0.04 0.03"/>
        </geometry>
    </collision>
    </link>
    <gazebo reference="drivemotor_bl">
    <material>Gazebo/White</material>
    </gazebo>
    
    <joint name="chassis_joint14" type="fixed">
    <parent link="base_link"/>
    <child link="sidebot_l"/>
    <origin xyz="0 0 0"/>
    </joint>
    
    <link name="sidebot_l">
    <visual>
        <origin xyz="0 0.15 0.023" rpy="0 0 0"/>
        <geometry>
            <box size="0.5 0.01 0.03"/>
        </geometry>
        <material name="white"/>
    </visual>
    <collision>
        <origin xyz="0 0.15 0.023" rpy="0 0 0"/>
        <geometry>
            <box size="0.5 0.01 0.03"/>
        </geometry>
    </collision>
    </link>
    <gazebo reference="sidebot_l">
    <material>Gazebo/White</material>
    </gazebo>
    
    <joint name="chassis_joint15" type="fixed">
    <parent link="base_link"/>
    <child link="sidebot_r"/>
    <origin xyz="0 0 0"/>
    </joint>
    
    <link name="sidebot_r">
    <visual>
        <origin xyz="0 -0.15 0.023" rpy="0 0 0"/>
        <geometry>
            <box size="0.5 0.01 0.03"/>
        </geometry>
        <material name="white"/>
    </visual>
    <collision>
        <origin xyz="0 -0.15 0.023" rpy="0 0 0"/>
        <geometry>
            <box size="0.5 0.01 0.03"/>
        </geometry>
    </collision>
    </link>
    <gazebo reference="sidebot_r">
    <material>Gazebo/White</material>
    </gazebo>
    
    <!-- Front LEFT WHEEL -->

    <joint name="Front_left_wheel_joint" type="continuous">
    <parent link="base_link"/>
    <child link="Front_left_wheel"/>
    <origin xyz="0.25 0.19 0.023" rpy="-${pi/2} 0 0"/>
    <axis xyz="0 0 1"/>
    </joint>
    
    <link name="Front_left_wheel">
    <visual>
        <geometry>
            <cylinder length="0.04" radius="0.06" />
        </geometry>
        <material name="blue"/>
    </visual>
    <collision>
        <geometry>
            <cylinder length="0.04" radius="0.06" />
        </geometry>
    </collision>
    <xacro:inertial_cylinder mass="0.2" length="0.05" radius="0.06">
        <origin xyz="0 0 0" rpy="0 0 0"/>
    </xacro:inertial_cylinder>
    </link>
    <gazebo reference="Front_left_wheel">
    <material>Gazebo/Black</material>
    </gazebo>
    
    <!-- Rear LEFT WHEEL -->

    <joint name="Rear_left_wheel_joint" type="continuous">
    <parent link="base_link"/>
    <child link="Rear_left_wheel"/>
    <origin xyz="-0.25 0.19 0.023" rpy="-${pi/2} 0 0"/>
    <axis xyz="0 0 1"/>
    </joint>
    
    <link name="Rear_left_wheel">
    <visual>
        <geometry>
            <cylinder length="0.04" radius="0.06" />
        </geometry>
        <material name="blue"/>
    </visual>
    <collision>
        <geometry>
            <cylinder length="0.04" radius="0.06" />
        </geometry>
    </collision>
    <xacro:inertial_cylinder mass="0.2" length="0.05" radius="0.06">
        <origin xyz="0 0 0" rpy="0 0 0"/>
    </xacro:inertial_cylinder>
    </link>
    <gazebo reference="Rear_left_wheel">
    <material>Gazebo/Black</material>
    <mu1 value="0.001"/>
    <mu2 value="0.001"/>
    </gazebo>
    
    <!-- Front RIGHT WHEEL -->

    <joint name="Front_right_wheel_joint" type="continuous">
    <parent link="base_link"/>
    <child link="Front_right_wheel"/>
    <origin xyz="0.25 -0.19 0.023" rpy="${pi/2} 0 0"/>
    <axis xyz="0 0 -1"/>
    </joint>

    <link name="Front_right_wheel">
    <visual>
        <geometry>
            <cylinder length="0.04" radius="0.06" />
        </geometry>
        <material name="blue"/>
    </visual>
    <collision>
        <geometry>
            <cylinder length="0.04" radius="0.06" />
        </geometry>
    </collision>
    <xacro:inertial_cylinder mass="0.2" length="0.05" radius="0.06">
        <origin xyz="0 0 0" rpy="0 0 0"/>
    </xacro:inertial_cylinder>
    </link>
    <gazebo reference="Front_right_wheel">
    <material>Gazebo/Black</material>
    </gazebo>
    
    <!-- Rear RIGHT WHEEL -->

    <joint name="Rear_right_wheel_joint" type="continuous">
    <parent link="base_link"/>
    <child link="Rear_right_wheel"/>
    <origin xyz="-0.25 -0.19 0.023" rpy="${pi/2} 0 0"/>
    <axis xyz="0 0 -1"/>
    </joint>

    <link name="Rear_right_wheel">
    <visual>
        <geometry>
            <cylinder length="0.04" radius="0.06" />
        </geometry>
        <material name="blue"/>
    </visual>
    <collision>
        <geometry>
            <cylinder length="0.04" radius="0.06" />
        </geometry>
    </collision>
    <xacro:inertial_cylinder mass="0.2" length="0.05" radius="0.06">
        <origin xyz="0 0 0" rpy="0 0 0"/>
    </xacro:inertial_cylinder>
    </link>
    <gazebo reference="Rear_right_wheel">
    <material>Gazebo/Black</material>
    <mu1 value="0.001"/>
    <mu2 value="0.001"/>
    </gazebo>
    
    
</robot>
